Workbook

Sheet ReadMe
B3: Tab Coloring Legend
C4: Biz Case Inputs
C5: Control Panel
C6: Analysis
C7: Summary

Sheet Gross-to-Net Process
B1: Initial Data
B4: The Gross-to-Net Planning approach - Wholesale
B5: The Sales planning function uses a building block approach to forecasting final net sales
B7: OrderType | C7: Definition
B8: Pre-Orders | C8: The Orders on books taken approx. 6 months before the season begins
B9: Cancellations | C9: The Pre-Orders that cannot be fulfilled or customers are permitted to cancel before delivery
B10: Re-Orders | C10: Additional In-Season orders placed by customers fufilled from available free stock in warehouse
B11: Stock Clearance | C11: Any old season stock the business is willing to sell to a customer
B12: Returns | C12: Any stock the business agreees to take back to the warehouse from a customer
B14: Net Sales FC (forecast) = | C14: Pre-Orders on Book - Forecast Cancellation + Forecast Re-Order + Forecast Stock Clearance - Forecast Returns
B15: Actual Net Sales = | C15: Pre-Orders Invoiced + Re-Orders Invoiced + Stock Clearance Invoiced - Returns Processed
B17: KPI | C17: Definition
B18: Cancellation % Mix | C18: The proportion of the total pre-orderbook that was cancelled for a given time period
B19: % Rate | C19: Re-Order, Stock Clearance or Return volume vs Total Invoiced Pre-Orders for a given time period

Sheet Account Information
A1: Initial Data
A2: Key Account Descriptions
A3: Name | B3: Product Vertical | C3: Description | F3: Product Vertical | G3: Name | H3: Description
A4: Hanover & Hearth | B4: Lifestyle / Sport | C4: Precise, premium department store | F4: Lifestyle | G4: Scale | H4: The "King of Tiers" in sports lifestyle
A5: Vanguard Wilds | B5: Sport | C5: Tech-wear for the Great Outdoors | G5: Swift-Pulse | H5: Experimental street-culture labs
A6: Swift-Pulse | B6: Lifestyle | C6: Experimental street-culture labs | G6: Vault | H6: Staple sneaker archives
A7: Velocity Labs | B7: Sport | C7: Biometric-focused sprinting gear | G7: Velvet & Vice | H7: Elite luxury
A8: Velvet & Vice | B8: Lifestyle | C8: Elite luxury | F8: Lifestyle / Sport | G8: Aurelian & Co. | H8: Prestigious, multi-level luxury spire
A9: Titan Sport | B9: Sport | C9: Mass-market muscle | G9: Axiom Street | H9: Endless digital fashion scroll
A10: Nordic Nord | B10: Sport | C10: Urban-armor optimized for the crumbling wild | G10: Hanover & Hearth | H10: Precise, premium department store
A11: Omni-Arena | B11: Sport | C11: Massive multi-sport hubs | F11: Sport | G11: Agora Athletics | H11: Digital-first performance gear
A12: Aurelian & Co. | B12: Lifestyle / Sport | C12: Prestigious, multi-level luxury spire | G12: Nordic Nord | H12: Urban-armor optimized for the crumbling wild
A13: Agora Athletics | B13: Sport | C13: Digital-first performance gear | G13: Omni-Arena | H13: Massive multi-sport hubs
A14: Axiom Street | B14: Lifestyle / Sport | C14: Endless digital fashion scroll | G14: Strike-Point | H14: Pinicle sporting aesthetics
A15: Vault | B15: Lifestyle | C15: Staple sneaker archives | G15: Titan Sport | H15: Mass-market muscle
A16: Strike-Point | B16: Sport | C16: Pinicle sporting aesthetics | G16: Vanguard Wilds | H16: Tech-wear for the Great Outdoors
A17: Scale | B17: Lifestyle | C17: The "King of Tiers" in sports lifestyle | G17: Velocity Labs | H17: Biometric-focused sprinting gear
A18: Field Accounts | B18: Field Accounts | C18: Generalist

Sheet Hypotesis Panel
B1: Hypotesis
B3: 1) EMEA Spring/Summer Lenghtin Weeks = 26 weeks | F3: 26 | G3: modify in case of different lenght
B5: Fase | C5: Period | D5: Exp SellOut | E5: What's appening
B6: Launch | C6: WK1–4 | D6: 0.05 | E6: First deliveries, floor set
B7: Build | C7: WK5–10 | D7: 0.35 | E7: Peak sell-in, replenishment start
B8: Peak | C8: WK10–18 | D8: 0.5 | E8: Max sell-out velocity | F8: we are in WK | G8: 14 | H8: scroll to choose the week
B9: Markdown Risk | C9: WK19–22 | D9: 0.08 | E9: Inventory correction
B10: Exit | C10: WK22–26 | D10: 0.02 | E10: Clearance / transition FW
B13: 2) Hypotetical Sell-out Distribution x week - Seasonality
B15: Sell-out % x week | C15: WK | D15: Fase % | E15: Cumulated | F15: Quarter
B16: =$D$16/COUNT($C$16:$C$19) -> 0.0125 | C16: 1 | D16: =D6 -> 0.05 | E16: =B16 -> 0.0125 | F16: =E28 -> 0.5875
B17: =$D$16/COUNT($C$16:$C$19) -> 0.0125 | C17: 2 | E17: =B17+E16 -> 0.025
B18: =$D$16/COUNT($C$16:$C$19) -> 0.0125 | C18: 3 | E18: =B18+E17 -> 0.0375
B19: =$D$16/COUNT($C$16:$C$19) -> 0.0125 | C19: 4 | E19: =B19+E18 -> 0.05
B20: =$D$20/COUNT($C$20:$C$25) -> 0.058333333 | C20: 5 | D20: =D7 -> 0.35 | E20: =B20+E19 -> 0.10833333
B21: =$D$20/COUNT($C$20:$C$25) -> 0.058333333 | C21: 6 | E21: =B21+E20 -> 0.16666667
B22: =$D$20/COUNT($C$20:$C$25) -> 0.058333333 | C22: 7 | E22: =B22+E21 -> 0.225 | G22: Q1
B23: =$D$20/COUNT($C$20:$C$25) -> 0.058333333 | C23: 8 | E23: =B23+E22 -> 0.28333333
B24: =$D$20/COUNT($C$20:$C$25) -> 0.058333333 | C24: 9 | E24: =B24+E23 -> 0.34166667
B25: =$D$20/COUNT($C$20:$C$25) -> 0.058333333 | C25: 10 | E25: =B25+E24 -> 0.4
B26: =$D$26/COUNT($C$26:$C$33) -> 0.0625 | C26: 11 | D26: =D8 -> 0.5 | E26: =B26+E25 -> 0.4625
B27: =$D$26/COUNT($C$26:$C$33) -> 0.0625 | C27: 12 | E27: =B27+E26 -> 0.525
B28: =$D$26/COUNT($C$26:$C$33) -> 0.0625 | C28: 13 | E28: =B28+E27 -> 0.5875
B29: =$D$26/COUNT($C$26:$C$33) -> 0.0625 | C29: 14 | E29: =B29+E28 -> 0.65 | F29: =E41-F16 -> 0.4425 | G29: We are here
B30: =$D$26/COUNT($C$26:$C$33) -> 0.0625 | C30: 15 | E30: =B30+E29 -> 0.7125
B31: =$D$26/COUNT($C$26:$C$33) -> 0.0625 | C31: 16 | E31: =B31+E30 -> 0.775
B32: =$D$26/COUNT($C$26:$C$33) -> 0.0625 | C32: 17 | E32: =B32+E31 -> 0.8375
B33: =$D$26/COUNT($C$26:$C$33) -> 0.0625 | C33: 18 | E33: =B33+E32 -> 0.9
B34: =$D$34/COUNT($C$34:$C$37) -> 0.02 | C34: 19 | D34: =D9 -> 0.08 | E34: =B34+E33 -> 0.92
B35: =$D$34/COUNT($C$34:$C$37) -> 0.02 | C35: 20 | E35: =B35+E34 -> 0.94 | G35: Q2
B36: =$D$34/COUNT($C$34:$C$37) -> 0.02 | C36: 21 | E36: =B36+E35 -> 0.96
B37: =$D$34/COUNT($C$34:$C$37) -> 0.02 | C37: 22 | E37: =B37+E36 -> 0.98
B38: =$D$38/COUNT($C$38:$C$41) -> 0.0125 | C38: 23 | D38: 0.05 | E38: =B38+E37 -> 0.9925
B39: =$D$38/COUNT($C$38:$C$41) -> 0.0125 | C39: 24 | E39: =B39+E38 -> 1.005
B40: =$D$38/COUNT($C$38:$C$41) -> 0.0125 | C40: 25 | E40: =B40+E39 -> 1.0175
B41: =$D$38/COUNT($C$38:$C$41) -> 0.0125 | C41: 26 | E41: =B41+E40 -> 1.03
B44: 3) Apparel/Shoes Split
B46: I will assume that the Apparel/Shoes sales split to be 8.22% as LY Q2 (calculation in "SS24 Q2 Data") | F46: ='SS24 Q2 Data'!AB5 -> 0.082166497
B51: 3) Revertig "Actual Net Sales" formula to Extract "Pre-Order Invoiced"
B53: IF | C53: Actual Net Sales = | D53: Pre-Orders Invoiced + Re-Orders Invoiced + Stock Clearance Invoiced - Returns Processed
...

Sheet Available Stock
B2: Initial Data | G2: Stock Assesment
B3: Available SS25 Q2 Stock in Warehouse | G3: No visibility on Model SKU.
B5: WAREHOUSE STOCK | G5: Category | H5: Current Season | I5: Old Season | J5: Total | K5: Q2 Orderbook | L5: Coverage Ratio
B6: Shoes | D6: Apparel | G6: Shoes | H6: 973440 | I6: 584064 | J6: =SUM(H6:I6) -> 1557504 | K6: =SUM(Table3[[Actual Order Book Shoes ]]) -> 748800 | L6: =J6/K6 -> 2.08
B7: Current season | C7: Old Season | D7: Current Season | E7: Old Season | G7: Apparel | H7: 145552 | I7: 40755 | J7: =SUM(H7:I7) -> 186307 | K7: =SUM(Table3[[Actual Order Book Apparel ]]) -> 100381 | L7: =J7/K7 -> 1.8559986
B8: 973440 | C8: 584064 | D8: 145552.45 | E8: 40754.686 | G8: Total | H8: =SUM(H6:H7) -> 1118992 | I8: =SUM(I6:I7) -> 624819 | J8: =SUM(J6:J7) -> 1743811 | K8: 849181 | L8: =J8/K8 -> 2.053521
G10: Current Shoe stock vs Q2 OB: | J10: =H6-K6 -> 224640 | K10: surplus units available for re-orders
G11: Current Apparel stock vs Q2 OB: | J11: =H7-K7 -> 45171
G12: Potential Clearence Revenuee: | J12: =I6*M12 -> 28383598 | K12: Shoe | L12: Clearance ASP | M12: ='Hypotesis Panel'!E59 -> 48.596725
G13: Potential Clearence Revenuee: | J13: =I7*M13 -> 1475079.3 | K13: Apparel | L13: Clearance ASP | M13: ='Hypotesis Panel'!E60 -> 36.193824
J14: =SUM(J12:J13) -> 29858677

Sheet SS24 Q2 Data
A1: Initial Data | P1: Analysis | AP1: LY Growth Apparel | AQ1: 0.68 | AR1: external sources
A2: SS24 Q2 Net Sales, Cancellation Mix % and Rates % | R2: I've reverted the formulat to extract the Old PreOrder booked value | AD2: Weighted % avg | AP2: LY Growth Shoes | AQ2: 0.25
E4: LY Q2 Shoes | J4: LY Q2 Apparel | P4: LY Q2 Total (Shoes+Apparel) | T4: LY Q2 Shoes (units) | X4: LY Q2 Apparel (units) | AL4: Text in blue is my hypotesis if conditions are met, conditions in the document
C5: Totals | E5: =SUM('SS24 Q2 Data'!$E$7:$E$29) -> 785600 | F5: =SUMPRODUCT('SS24 Q2 Data'!$F$7:$F$29,'SS24 Q2 Data'!$P$7:$P$29)/SUM('SS24 Q2 Data'!$P$7:$P$29) -> 0.13712505 | G5: =SUMPRODUCT($G$7:$G$29,'SS24 Q2 Data'!$P$7:$P$29)/SUM('SS24 Q2 Data'!$P$7:$P$29) -> 0.14914765 | H5: =SUMPRODUCT($H$7:$H$29,'SS24 Q2 Data'!$P$7:$P$29)/SUM('SS24 Q2 Data'!$P$7:$P$29) -> 0.011346493 | I5: =SUMPRODUCT($I$7:$I$29,'SS24 Q2 Data'!$P$7:$P$29)/SUM('SS24 Q2 Data'!$P$7:$P$29) -> 0.033306571 | J5: =SUM('SS24 Q2 Data'!$J$7:$J$29) -> 64550 | K5: =SUMPRODUCT('SS24 Q2 Data'!$K$7:$K$29,'SS24 Q2 Data'!$Q$7:$Q$29)/SUM('SS24 Q2 Data'!$Q$7:$Q$29) -> 0.17246251 | L5: =SUMPRODUCT($L$7:$L$29,'SS24 Q2 Data'!$Q$7:$Q$29)/SUM('SS24 Q2 Data'!$Q$7:$Q$29) -> 0.14708894 | M5: =SUMPRODUCT($M$7:$M$29,'SS24 Q2 Data'!$Q$7:$Q$29)/SUM('SS24 Q2 Data'!$Q$7:$Q$29) -> 0.0021136871 | N5: =SUMPRODUCT($N$7:$N$29,'SS24 Q2 Data'!$Q$7:$Q$29)/SUM('SS24 Q2 Data'!$Q$7:$Q$29) -> 0.042690528 | P5: =SUM('SS24 Q2 Data'!$P$7:$P$29) -> 793485.24 | Q5: =SUM('SS24 Q2 Data'!$Q$7:$Q$29) -> 69107.68 | R5: =SUM('SS24 Q2 Data'!$R$7:$R$29) -> 850150 | S5: =SUM('SS24 Q2 Data'!$S$7:$S$29) -> 862592.92 | T5: =SUM('SS24 Q2 Data'!$T$7:$T$29) -> 108808 | U5: =SUM('SS24 Q2 Data'!$U$7:$U$29) -> 118347 | V5: =SUM('SS24 Q2 Data'!$V$7:$V$29) -> 9003 | W5: =SUM('SS24 Q2 Data'!$W$7:$W$29) -> 26430 | X5: =SUM('SS24 Q2 Data'!$X$7:$X$29) -> 11917 | Y5: =SUM('SS24 Q2 Data'!$Y$7:$Y$29) -> 10165 | Z5: =SUM('SS24 Q2 Data'!$Z$7:$Z$29) -> 146 | AA5: =SUM('SS24 Q2 Data'!$AA$7:$AA$29) -> 146 | AB5: =SUMPRODUCT($AB$7:$AB$29,$E$7:$E$29)/SUM($E$7:$E$29) -> 0.082166497 | AD5: =SUM('SS24 Q2 Data'!$AD$7:$AD$29) -> 120725 | AE5: =SUMPRODUCT('SS24 Q2 Data'!$AE$7:$AE$29,'SS24 Q2 Data'!$S$7:$S$29)/SUM('SS24 Q2 Data'!$S$7:$S$29) -> 0.13995594 | AF5: =SUM('SS24 Q2 Data'!$AF$7:$AF$29) -> 128512 | AG5: =SUMPRODUCT('SS24 Q2 Data'!$AG$7:$AG$29,'SS24 Q2 Data'!$R$7:$R$29)/SUM('SS24 Q2 Data'!$R$7:$R$29) -> 0.15116391 | AH5: =SUM(AH7:AH29) -> 9149 | AI5: =SUMPRODUCT(AI7:AI29,'SS24 Q2 Data'!$S$7:$S$29)/SUM('SS24 Q2 Data'!$S$7:$S$29) -> 0.010606394 | AJ5: =SUM(AJ7:AJ29) -> 26576 | AK5: =SUMPRODUCT(AK7:AK29,'SS24 Q2 Data'!$S$7:$S$29)/SUM('SS24 Q2 Data'!$S$7:$S$29) -> 0.030809434 | AL5: =SUMPRODUCT(Table3[FC Cancellation Mix %Shoes],Table3[Tommaso''s FC Q2 SS5 Net Sales FC Shoes])/SUM(Table3[Tommaso''s FC Q2 SS5 Net Sales FC Shoes]) -> 0.072669573 | AM5: =SUMPRODUCT(Table3[Re-Order Rate % FC],Table3[Tommaso''s FC Q2 SS5 Net Sales FC Shoes])/SUM(Table3[Tommaso''s FC Q2 SS5 Net Sales FC Shoes]) -> 0.13121821 | AN5: =SUMPRODUCT(Table3[Stock Clearance Rate %2],Table3[Tommaso''s FC Q2 SS5 Net Sales FC Shoes])/SUM(Table3[Tommaso''s FC Q2 SS5 Net Sales FC Shoes]) -> 0.01 | AO5: =SUMPRODUCT(Table3[Returns Rate %2],Table3[Tommaso''s FC Q2 SS5 Net Sales FC Shoes])/SUM(Table3[Tommaso''s FC Q2 SS5 Net Sales FC Shoes]) -> 0.03
A6: Sub Region | B6: Market | C6: Account | D6: Client Tier | E6: Net Sales Invoiced Shoes | F6: Pre-Order Cancellations Mix % | G6: Re-Order Rate % | H6: Stock Clearance Rate % | I6: Returns Rate % | J6: Net Sales Invoiced Apparel | K6: Pre-Order Cancellations Mix %2 | L6: Re-Order Rate %4 | M6: Stock Clearance Rate %5 | N6: Returns Rate %6 | O6: Returns Rate %7 | P6: Pre-Orders Booked LYQ2 (shoes) | Q6: Pre-Orders Booked LYQ2 (apparel) | R6: Tot Net Sales Invoiced (units) | S6: Tot PreOrder Invoiced (units) | T6: Pre-Order Cancellations Mix Shoes | U6: Re-Order Rate %7 | V6: Stock Clearance Rate %8 | W6: Returns Rate %9 | X6: Pre-Order Cancellations Mix %Apparel | Y6: Re-Order Rate %11 | Z6: Stock Clearance Rate %12 | AA6: Returns Rate %13 | AB6: Apparel vs Shoes Sell/Out | AC6: Column1 | AD6: Tot Cancellation | AE6: Cancellation % | AF6: ToT Reorders | AG6: Reorder % | AH6: ToT Stock Clearance | AI6: Tot Stock Clearance % | AJ6: ToT Retruns | AK6: Tot Returns % | AL6: FC Cancellation Mix %Shoes | AM6: Re-Order Rate % FC | AN6: Stock Clearance Rate %2 | AO6: Returns Rate %2 | AP6: Exp Shoes PreOrder Growth Rate | AQ6: Exp Apparel PreOrder Growth Rate | AR6: Tommaso's FC Q2 SS5 Net Sales FC Shoes | AS6: Exp YoY Shoes | AT6: Tommaso's FC Q2 SS5 Net Sales FC Apparel | AU6: Exp YoY Apparel | AV6: Actual Order Book Shoes | AW6: Actual Order Book Apparel | AX6: Deviation from Tommaso's suggestion Shoes | AY6: Deviation from Tommaso's suggestion Apparel | AZ6: YoY on Net Sales Shoes | BA6: YoY on Net Sales Apparel
A7: North | B7: BeNeLux | C7: Field Accounts | D7: Monitor | E7: 34800 | F7: 0.208 | G7: 0.264 | H7: 0.104 | I7: 0.055 | J7: 1500 | K7: 0.142 | L7: 6.481 | M7: 0 | N7: 0.144 | P7: =IFERROR(E7/(1-F7+G7+H7-I7),0) -> 31493.213 | Q7: =IFERROR(J7/(1+L7+M7-N7-K7),0) -> 208.47811 | R7: =E7+J7 -> 36300 | S7: ='SS24 Q2 Data'!$P13+Q7 -> 6489.0085 | T7: =ROUND(P7*F7,0) -> 6551 | U7: =ROUND(P7*G7,0) -> 8314 | V7: =ROUND(P7*H7,0) -> 3275 | W7: =ROUND(P7*I7,0) -> 1732 | X7: =ROUND(Q7*K7,0) -> 30 | Y7: =ROUND(Q7*L7,0) -> 1351 | Z7: =ROUND(Q7*M7,0) -> 0 | AA7: =ROUND(Q7*M7,0) -> 0 | AB7: =J7/E7 -> 0.043103448 | AD7: =Table3[[#This Row],[Pre-Order Cancellations Mix Shoes]]+Table3[[#This Row],[Pre-Order Cancellations Mix %Apparel]] -> 6581 | AE7: =Table3[[#This Row],[Tot Cancellation]]/Table3[[#This Row],[Tot PreOrder Invoiced (units)]] -> 1.0141765 | AF7: =Table3[[#This Row],[Re-Order Rate %7]]+Table3[[#This Row],[Re-Order Rate %11]] -> 9665 | AG7: =Table3[[#This Row],[ToT Reorders]]/Table3[[#This Row],[Tot Net Sales Invoiced (units)]] -> 0.26625344 | AH7: =Table3[[#This Row],[Stock Clearance Rate %8]]+Table3[[#This Row],[Stock Clearance Rate %12]] -> 3275 | AI7: =Table3[[#This Row],[ToT Stock Clearance]]/Table3[[#This Row],[Tot PreOrder Invoiced (units)]] -> 0.5046996 | AJ7: =Table3[[#This Row],[Returns Rate %13]]+Table3[[#This Row],[Returns Rate %9]] -> 1732 | AK7: =Table3[[#This Row],[ToT Retruns]]/Table3[[#This Row],[Tot PreOrder Invoiced (units)]] -> 0.26691289 | AL7: 0.1 | AM7: 0.15 | AN7: 0.01 | AO7: 0.03 | AP7: 0.1 | AQ7: =IF(Table3[[#This Row],[Re-Order Rate %4]]-Table3[[#This Row],[Pre-Order Cancellations Mix %2]]-Table3[[#This Row],[Returns Rate %6]]<$AQ$1,$AQ$1,Table3[[#This Row],[Re-Order Rate %4]]-Table3[[#This Row],[Pre-Order Cancellations Mix %2]]-Table3[[#This Row],[Returns Rate %6]]) -> 6.195 | AR7: =Table3[[#This Row],[Pre-Orders Booked LYQ2 (shoes)]]*(1+Table3[[#This Row],[Re-Order Rate % FC]]+Table3[[#This Row],[Stock Clearance Rate %2]]+Table3[[#This Row],[Returns Rate %2]]-Table3[[#This Row],[FC Cancellation Mix %Shoes]]+Table3[[#This Row],[Exp Shoes PreOrder Growth Rate]]) -> 37476.923 | AS7: =Table3[[#This Row],[Tommaso''s FC Q2 SS5 Net Sales FC Shoes]]/Table3[[#This Row],[Net Sales Invoiced Shoes]]-1 -> 0.076923077 | AT7: =Table3[[#This Row],[Pre-Orders Booked LYQ2 (apparel)]]*(1+Table3[[#This Row],[Re-Order Rate % FC]]+Table3[[#This Row],[Stock Clearance Rate %2]]+Table3[[#This Row],[Returns Rate %2]]-Table3[[#This Row],[FC Cancellation Mix %Shoes]]+Table3[[#This Row],[Exp Apparel PreOrder Growth Rate]]) -> 1518.763 | AU7: =Table3[[#This Row],[Tommaso''s FC Q2 SS5 Net Sales FC Apparel]]/Table3[[#This Row],[Net Sales Invoiced Apparel]]-1 -> 0.012508687 | AV7: 33600 | AW7: 3564 | AX7: =Table3[[#This Row],[Actual Order Book Shoes ]]/Table3[[#This Row],[Tommaso''s FC Q2 SS5 Net Sales FC Shoes]]-1 -> -0.10344828 | AY7: =Table3[[#This Row],[Actual Order Book Apparel ]]/Table3[[#This Row],[Tommaso''s FC Q2 SS5 Net Sales FC Apparel]]-1 -> 1.3466465 | AZ7: =Table3[[#This Row],[Actual Order Book Shoes ]]/Table3[[#This Row],[Net Sales Invoiced Shoes]]-1 -> -0.034482759 | BA7: =IFERROR(Table3[[#This Row],[Actual Order Book Apparel ]]/Table3[[#This Row],[Net Sales Invoiced Apparel]]-1,"") -> 1.376
A8: Central | B8: Germany | C8: Field Accounts | E8: 171000 | F8: 0.103 | G8: 0.392 | H8: 0.02 | I8: 0.019 | J8: 6500 | K8: 0.174 | L8: 0.333 | M8: 0 | N8: 0.103 | P8: =IFERROR(E8/(1-F8+G8+H8-I8),0) -> 132558.14 | Q8: =IFERROR(J8/(1+L8+M8-N8-K8),0) -> 6155.303 | R8: =E8+J8 -> 177500 | S8: ='SS24 Q2 Data'!$P8+Q8 -> 138713.44 | T8: =ROUND(P8*F8,0) -> 13653 | U8: =ROUND(P8*G8,0) -> 51963 | V8: =ROUND(P8*H8,0) -> 2651 | W8: =ROUND(P8*I8,0) -> 2519 | X8: =ROUND(Q8*K8,0) -> 1071 | Y8: =ROUND(Q8*L8,0) -> 2050 | Z8: =ROUND(Q8*M8,0) -> 0 | AA8: =ROUND(Q8*M8,0) -> 0 | AB8: =J8/E8 -> 0.038011696 | AD8: =Table3[[#This Row],[Pre-Order Cancellations Mix Shoes]]+Table3[[#This Row],[Pre-Order Cancellations Mix %Apparel]] -> 14724 | AE8: =Table3[[#This Row],[Tot Cancellation]]/Table3[[#This Row],[Tot PreOrder Invoiced (units)]] -> 0.10614689 | AF8: =Table3[[#This Row],[Re-Order Rate %7]]+Table3[[#This Row],[Re-Order Rate %11]] -> 54013 | AG8: =Table3[[#This Row],[ToT Reorders]]/Table3[[#This Row],[Tot Net Sales Invoiced (units)]] -> 0.30429859 | AH8: =Table3[[#This Row],[Stock Clearance Rate %8]]+Table3[[#This Row],[Stock Clearance Rate %12]] -> 2651 | AI8: =Table3[[#This Row],[ToT Stock Clearance]]/Table3[[#This Row],[Tot PreOrder Invoiced (units)]] -> 0.019111342 | AJ8: =Table3[[#This Row],[Returns Rate %13]]+Table3[[#This Row],[Returns Rate %9]] -> 2519 | AK8: =Table3[[#This Row],[ToT Retruns]]/Table3[[#This Row],[Tot PreOrder Invoiced (units)]] -> 0.01815974 | AL8: 0.1 | AM8: 0.15 | AN8: 0.01 | AO8: 0.03 | AP8: =$AQ$2 -> 0.25 | AQ8: =IF(Table3[[#This Row],[Re-Order Rate %4]]-Table3[[#This Row],[Pre-Order Cancellations Mix %2]]-Table3[[#This Row],[Returns Rate %6]]<$AQ$1,$AQ$1,Table3[[#This Row],[Re-Order Rate %4]]-Table3[[#This Row],[Pre-Order Cancellations Mix %2]]-Table3[[#This Row],[Returns Rate %6]]) -> 0.68 | AR8: =Table3[[#This Row],[Pre-Orders Booked LYQ2 (shoes)]]*(1+Table3[[#This Row],[Re-Order Rate % FC]]+Table3[[#This Row],[Stock Clearance Rate %2]]+Table3[[#This Row],[Returns Rate %2]]-Table3[[#This Row],[FC Cancellation Mix %Shoes]]+Table3[[#This Row],[Exp Shoes PreOrder Growth Rate]]) -> 177627.91 | AS8: =Table3[[#This Row],[Tommaso''s FC Q2 SS5 Net Sales FC Shoes]]/Table3[[#This Row],[Net Sales Invoiced Shoes]]-1 -> 0.03875969 | AT8: =Table3[[#This Row],[Pre-Orders Booked LYQ2 (apparel)]]*(1+Table3[[#This Row],[Re-Order Rate % FC]]+Table3[[#This Row],[Stock Clearance Rate %2]]+Table3[[#This Row],[Returns Rate %2]]-Table3[[#This Row],[FC Cancellation Mix %Shoes]]+Table3[[#This Row],[Exp Apparel PreOrder Growth Rate]]) -> 10894.886 | AU8: =Table3[[#This Row],[Tommaso''s FC Q2 SS5 Net Sales FC Apparel]]/Table3[[#This Row],[Net Sales Invoiced Apparel]]-1 -> 0.67613636 | AV8: 115000 | AW8: 20342 | AX8: =Table3[[#This Row],[Actual Order Book Shoes ]]/Table3[[#This Row],[Tommaso''s FC Q2 SS5 Net Sales FC Shoes]]-1 -> -0.35257921 | AY8: =Table3[[#This Row],[Actual Order Book Apparel ]]/Table3[[#This Row],[Tommaso''s FC Q2 SS5 Net Sales FC Apparel]]-1 -> 0.86711447 | AZ8: =Table3[[#This Row],[Actual Order Book Shoes ]]/Table3[[#This Row],[Net Sales Invoiced Shoes]]-1 -> -0.32748538 | BA8: =IFERROR(Table3[[#This Row],[Actual Order Book Apparel ]]/Table3[[#This Row],[Net Sales Invoiced Apparel]]-1,"") -> 2.1295385
A9: North | B9: United Kingdom | C9: Field Accounts | E9: 53300 | F9: 0.107 | G9: 0.189 | H9: 0 | I9: 0.094 | J9: 6100 | K9: 0.081 | L9: 0.15 | M9: 0 | N9: 0.033 | P9: =IFERROR(E9/(1-F9+G9+H9-I9),0) -> 53947.368 | Q9: =IFERROR(J9/(1+L9+M9-N9-K9),0) -> 5888.0309 | R9: =E9+J9 -> 59400 | S9: ='SS24 Q2 Data'!$P10+Q9 -> 35152.625 | T9: =ROUND(P9*F9,0) -> 5772 | U9: =ROUND(P9*G9,0) -> 10196 | V9: =ROUND(P9*H9,0) -> 0 | W9: =ROUND(P9*I9,0) -> 5071 | X9: =ROUND(Q9*K9,0) -> 477 | Y9: =ROUND(Q9*L9,0) -> 883 | Z9: =ROUND(Q9*M9,0) -> 0 | AA9: =ROUND(Q9*M9,0) -> 0 | AB9: =J9/E9 -> 0.11444653 | AD9: =Table3[[#This Row],[Pre-Order Cancellations Mix Shoes]]+Table3[[#This Row],[Pre-Order Cancellations Mix %Apparel]] -> 6249 | AE9: =Table3[[#This Row],[Tot Cancellation]]/Table3[[#This Row],[Tot PreOrder Invoiced (units)]] -> 0.17776766 | AF9: =Table3[[#This Row],[Re-Order Rate %7]]+Table3[[#This Row],[Re-Order Rate %11]] -> 11079 | AG9: =Table3[[#This Row],[ToT Reorders]]/Table3[[#This Row],[Tot Net Sales Invoiced (units)]] -> 0.18651515 | AH9: =Table3[[#This Row],[Stock Clearance Rate %8]]+Table3[[#This Row],[Stock Clearance Rate %12]] -> 0 | AI9: =Table3[[#This Row],[ToT Stock Clearance]]/Table3[[#This Row],[Tot PreOrder Invoiced (units)]] -> 0 | AJ9: =Table3[[#This Row],[Returns Rate %13]]+Table3[[#This Row],[Returns Rate %9]] -> 5071 | AK9: =Table3[[#This Row],[ToT Retruns]]/Table3[[#This Row],[Tot PreOrder Invoiced (units)]] -> 0.14425665 | AL9: 0.1 | AM9: 0.15 | AN9: 0.01 | AO9: 0.03 | AP9: =$AQ$2 -> 0.25 | AQ9: =IF(Table3[[#This Row],[Re-Order Rate %4]]-Table3[[#This Row],[Pre-Order Cancellations Mix %2]]-Table3[[#This Row],[Returns Rate %6]]<$AQ$1,$AQ$1,Table3[[#This Row],[Re-Order Rate %4]]-Table3[[#This Row],[Pre-Order Cancellations Mix %2]]-Table3[[#This Row],[Returns Rate %6]]) -> 0.68 | AR9: =Table3[[#This Row],[Pre-Orders Booked LYQ2 (shoes)]]*(1+Table3[[#This Row],[Re-Order Rate % FC]]+Table3[[#This Row],[Stock Clearance Rate %2]]+Table3[[#This Row],[Returns Rate %2]]-Table3[[#This Row],[FC Cancellation Mix %Shoes]]+Table3[[#This Row],[Exp Shoes PreOrder Growth Rate]]) -> 72289.474 | AS9: =Table3[[#This Row],[Tommaso''s FC Q2 SS5 Net Sales FC Shoes]]/Table3[[#This Row],[Net Sales Invoiced Shoes]]-1 -> 0.3562753 | AT9: =Table3[[#This Row],[Pre-Orders Booked LYQ2 (apparel)]]*(1+Table3[[#This Row],[Re-Order Rate % FC]]+Table3[[#This Row],[Stock Clearance Rate %2]]+Table3[[#This Row],[Returns Rate %2]]-Table3[[#This Row],[FC Cancellation Mix %Shoes]]+Table3[[#This Row],[Exp Apparel PreOrder Growth Rate]]) -> 10421.815 | AU9: =Table3[[#This Row],[Tommaso''s FC Q2 SS5 Net Sales FC Apparel]]/Table3[[#This Row],[Net Sales Invoiced Apparel]]-1 -> 0.70849421 | AV9: 30700 | AW9: 1231 | AX9: =Table3[[#This Row],[Actual Order Book Shoes ]]/Table3[[#This Row],[Tommaso''s FC Q2 SS5 Net Sales FC Shoes]]-1 -> -0.57531853 | AY9: =Table3[[#This Row],[Actual Order Book Apparel ]]/Table3[[#This Row],[Tommaso''s FC Q2 SS5 Net Sales FC Apparel]]-1 -> -0.88188237 | AZ9: =Table3[[#This Row],[Actual Order Book Shoes ]]/Table3[[#This Row],[Net Sales Invoiced Shoes]]-1 -> -0.42401501 | BA9: =IFERROR(Table3[[#This Row],[Actual Order Book Apparel ]]/Table3[[#This Row],[Net Sales Invoiced Apparel]]-1,"") -> -0.79819672
A10: Central | B10: Austria | C10: Field Accounts | E10: 38600 | F10: 0.035 | G10: 0.363 | H10: 0.004 | I10: 0.013 | J10: 3500 | K10: 0.059 | L10: 0.259 | M10: 0.051 | N10: 0.029 | P10: =IFERROR(E10/(1-F10+G10+H10-I10),0) -> 29264.594 | Q10: =IFERROR(J10/(1+L10+M10-N10-K10),0) -> 2864.1571 | R10: =E10+J10 -> 42100 | S10: ='SS24 Q2 Data'!$P11+Q10 -> 29099.251 | T10: =ROUND(P10*F10,0) -> 1024 | U10: =ROUND(P10*G10,0) -> 10623 | V10: =ROUND(P10*H10,0) -> 117 | W10: =ROUND(P10*I10,0) -> 380 | X10: =ROUND(Q10*K10,0) -> 169 | Y10: =ROUND(Q10*L10,0) -> 742 | Z10: =ROUND(Q10*M10,0) -> 146 | AA10: =ROUND(Q10*M10,0) -> 146 | AB10: =J10/E10 -> 0.090673575 | AD10: =Table3[[#This Row],[Pre-Order Cancellations Mix Shoes]]+Table3[[#This Row],[Pre-Order Cancellations Mix %Apparel]] -> 1193 | AE10: =Table3[[#This Row],[Tot Cancellation]]/Table3[[#This Row],[Tot PreOrder Invoiced (units)]] -> 0.040997619 | AF10: =Table3[[#This Row],[Re-Order Rate %7]]+Table3[[#This Row],[Re-Order Rate %11]] -> 11365 | AG10: =Table3[[#This Row],[ToT Reorders]]/Table3[[#This Row],[Tot Net Sales Invoiced (units)]] -> 0.26995249 | AH10: =Table3[[#This Row],[Stock Clearance Rate %8]]+Table3[[#This Row],[Stock Clearance Rate %12]] -> 263 | AI10: =Table3[[#This Row],[ToT Stock Clearance]]/Table3[[#This Row],[Tot PreOrder Invoiced (units)]] -> 0.0090380334 | AJ10: =Table3[[#This Row],[Returns Rate %13]]+Table3[[#This Row],[Returns Rate %9]] -> 526 | AK10: =Table3[[#This Row],[ToT Retruns]]/Table3[[#This Row],[Tot PreOrder Invoiced (units)]] -> 0.018076067 | AL10: 0.1 | AM10: 0.15 | AN10: 0.01 | AO10: 0.03 | AP10: =$AQ$2 -> 0.25 | AQ10: =IF(Table3[[#This Row],[Re-Order Rate %4]]-Table3[[#This Row],[Pre-Order Cancellations Mix %2]]-Table3[[#This Row],[Returns Rate %6]]<$AQ$1,$AQ$1,Table3[[#This Row],[Re-Order Rate %4]]-Table3[[#This Row],[Pre-Order Cancellations Mix %2]]-Table3[[#This Row],[Returns Rate %6]]) -> 0.68 | AR10: =Table3[[#This Row],[Pre-Orders Booked LYQ2 (shoes)]]*(1+Table3[[#This Row],[Re-Order Rate % FC]]+Table3[[#This Row],[Stock Clearance Rate %2]]+Table3[[#This Row],[Returns Rate %2]]-Table3[[#This Row],[FC Cancellation Mix %Shoes]]+Table3[[#This Row],[Exp Shoes PreOrder Growth Rate]]) -> 39214.556 | AS10: =Table3[[#This Row],[Tommaso''s FC Q2 SS5 Net Sales FC Shoes]]/Table3[[#This Row],[Net Sales Invoiced Shoes]]-1 -> 0.015921152 | AT10: =Table3[[#This Row],[Pre-Orders Booked LYQ2 (apparel)]]*(1+Table3[[#This Row],[Re-Order Rate % FC]]+Table3[[#This Row],[Stock Clearance Rate %2]]+Table3[[#This Row],[Returns Rate %2]]-Table3[[#This Row],[FC Cancellation Mix %Shoes]]+Table3[[#This Row],[Exp Apparel PreOrder Growth Rate]]) -> 5069.5581 | AU10: =Table3[[#This Row],[Tommaso''s FC Q2 SS5 Net Sales FC Apparel]]/Table3[[#This Row],[Net Sales Invoiced Apparel]]-1 -> 0.44844517 | AV10: 24900 | AW10: 2435 | AX10: =Table3[[#This Row],[Actual Order Book Shoes ]]/Table3[[#This Row],[Tommaso''s FC Q2 SS5 Net Sales FC Shoes]]-1 -> -0.36503171 | AY10: =Table3[[#This Row],[Actual Order Book Apparel ]]/Table3[[#This Row],[Tommaso''s FC Q2 SS5 Net Sales FC Apparel]]-1 -> -0.519682 | AZ10: =Table3[[#This Row],[Actual Order Book Shoes ]]/Table3[[#This Row],[Net Sales Invoiced Shoes]]-1 -> -0.35492228 | BA10: =IFERROR(Table3[[#This Row],[Actual Order Book Apparel ]]/Table3[[#This Row],[Net Sales Invoiced Apparel]]-1,"") -> -0.30428571
A11: South | B11: Spain | C11: Field Accounts | E11: 30800 | F11: 0.092 | G11: 0.308 | H11: 0 | I11: 0.042 | J11: 2500 | K11: 0.042 | L11: 0.615 | M11: 0 | N11: 0.017 | P11: =IFERROR(E11/(1-F11+G11+H11-I11),0) -> 26235.094 | Q11: =IFERROR(J11/(1+L11+M11-N11-K11),0) -> 1606.6838 | R11: =E11+J11 -> 33300 | S11: ='SS24 Q2 Data'!$P14+Q11 -> 5391.6952 | T11: =ROUND(P11*F11,0) -> 2414 | U11: =ROUND(P11*G11,0) -> 8080 | V11: =ROUND(P11*H11,0) -> 0 | W11: =ROUND(P11*I11,0) -> 1102 | X11: =ROUND(Q11*K11,0) -> 67 | Y11: =ROUND(Q11*L11,0) -> 988 | Z11: =ROUND(Q11*M11,0) -> 0 | AA11: =ROUND(Q11*M11,0) -> 0 | AB11: =J11/E11 -> 0.081168831 | AD11: =Table3[[#This Row],[Pre-Order Cancellations Mix Shoes]]+Table3[[#This Row],[Pre-Order Cancellations Mix %Apparel]] -> 2481 | AE11: =Table3[[#This Row],[Tot Cancellation]]/Table3[[#This Row],[Tot PreOrder Invoiced (units)]] -> 0.46015213 | AF11: =Table3[[#This Row],[Re-Order Rate %7]]+Table3[[#This Row],[Re-Order Rate %11]] -> 9068 | AG11: =Table3[[#This Row],[ToT Reorders]]/Table3[[#This Row],[Tot Net Sales Invoiced (units)]] -> 0.27231231 | AH11: =Table3[[#This Row],[Stock Clearance Rate %8]]+Table3[[#This Row],[Stock Clearance Rate %12]] -> 0 | AI11: =Table3[[#This Row],[ToT Stock Clearance]]/Table3[[#This Row],[Tot PreOrder Invoiced (units)]] -> 0 | AJ11: =Table3[[#This Row],[Returns Rate %13]]+Table3[[#This Row],[Returns Rate %9]] -> 1102 | AK11: =Table3[[#This Row],[ToT Retruns]]/Table3[[#This Row],[Tot PreOrder Invoiced (units)]] -> 0.20438841 | AL11: 0.1 | AM11: 0.15 | AN11: 0.01 | AO11: 0.03 | AP11: =$AQ$2 -> 0.25 | AQ11: =IF(Table3[[#This Row],[Re-Order Rate %4]]-Table3[[#This Row],[Pre-Order Cancellations Mix %2]]-Table3[[#This Row],[Returns Rate %6]]<$AQ$1,$AQ$1,Table3[[#This Row],[Re-Order Rate %4]]-Table3[[#This Row],[Pre-Order Cancellations Mix %2]]-Table3[[#This Row],[Returns Rate %6]]) -> 0.68 | AR11: =Table3[[#This Row],[Pre-Orders Booked LYQ2 (shoes)]]*(1+Table3[[#This Row],[Re-Order Rate % FC]]+Table3[[#This Row],[Stock Clearance Rate %2]]+Table3[[#This Row],[Returns Rate %2]]-Table3[[#This Row],[FC Cancellation Mix %Shoes]]+Table3[[#This Row],[Exp Shoes PreOrder Growth Rate]]) -> 35155.026 | AS11: =Table3[[#This Row],[Tommaso''s FC Q2 SS5 Net Sales FC Shoes]]/Table3[[#This Row],[Net Sales Invoiced Shoes]]-1 -> 0.14139693 | AT11: =Table3[[#This Row],[Pre-Orders Booked LYQ2 (apparel)]]*(1+Table3[[#This Row],[Re-Order Rate % FC]]+Table3[[#This Row],[Stock Clearance Rate %2]]+Table3[[#This Row],[Returns Rate %2]]-Table3[[#This Row],[FC Cancellation Mix %Shoes]]+Table3[[#This Row],[Exp Apparel PreOrder Growth Rate]]) -> 2843.8303 | AU11: =Table3[[#This Row],[Tommaso''s FC Q2 SS5 Net Sales FC Apparel]]/Table3[[#This Row],[Net Sales Invoiced Apparel]]-1 -> 0.13753213 | AV11: 20200 | AW11: 1675 | AX11: =Table3[[#This Row],[Actual Order Book Shoes ]]/Table3[[#This Row],[Tommaso''s FC Q2 SS5 Net Sales FC Shoes]]-1 -> -0.42540221 | AY11: =Table3[[#This Row],[Actual Order Book Apparel ]]/Table3[[#This Row],[Tommaso''s FC Q2 SS5 Net Sales FC Apparel]]-1 -> -0.41100565 | AZ11: =Table3[[#This Row],[Actual Order Book Shoes ]]/Table3[[#This Row],[Net Sales Invoiced Shoes]]-1 -> -0.34415584 | BA11: =IFERROR(Table3[[#This Row],[Actual Order Book Apparel ]]/Table3[[#This Row],[Net Sales Invoiced Apparel]]-1,"") -> -0.33
A12: North | B12: France | C12: Field Accounts | E12: 22800 | F12: 0.134 | G12: 0.451 | H12: 0 | I12: 0.064 | J12: 3800 | K12: 0.105 | L12: 0.159 | M12: 0 | N12: 0.04 | P12: =IFERROR(E12/(1-F12+G12+H12-I12),0) -> 18196.329 | Q12: =IFERROR(J12/(1+L12+M12-N12-K12),0) -> 3747.5345 | R12: =E12+J12 -> 26600 | S12: ='SS24 Q2 Data'!$P16+Q12 -> 93973.098 | T12: =ROUND(P12*F12,0) -> 2438 | U12: =ROUND(P12*G12,0) -> 8207 | V12: =ROUND(P12*H12,0) -> 0 | W12: =ROUND(P12*I12,0) -> 1165 | X12: =ROUND(Q12*K12,0) -> 393 | Y12: =ROUND(Q12*L12,0) -> 596 | Z12: =ROUND(Q12*M12,0) -> 0 | AA12: =ROUND(Q12*M12,0) -> 0 | AB12: =J12/E12 -> 0.16666667 | AD12: =Table3[[#This Row],[Pre-Order Cancellations Mix Shoes]]+Table3[[#This Row],[Pre-Order Cancellations Mix %Apparel]] -> 2831 | AE12: =Table3[[#This Row],[Tot Cancellation]]/Table3[[#This Row],[Tot PreOrder Invoiced (units)]] -> 0.030125643 | AF12: =Table3[[#This Row],[Re-Order Rate %7]]+Table3[[#This Row],[Re-Order Rate %11]] -> 8803 | AG12: =Table3[[#This Row],[ToT Reorders]]/Table3[[#This Row],[Tot Net Sales Invoiced (units)]] -> 0.33093985 | AH12: =Table3[[#This Row],[Stock Clearance Rate %8]]+Table3[[#This Row],[Stock Clearance Rate %12]] -> 0 | AI12: =Table3[[#This Row],[ToT Stock Clearance]]/Table3[[#This Row],[Tot PreOrder Invoiced (units)]] -> 0 | AJ12: =Table3[[#This Row],[Returns Rate %13]]+Table3[[#This Row],[Returns Rate %9]] -> 1165 | AK12: =Table3[[#This Row],[ToT Retruns]]/Table3[[#This Row],[Tot PreOrder Invoiced (units)]] -> 0.012397165 | AL12: 0.1 | AM12: 0.15 | AN12: 0.01 | AO12: 0.03 | AP12: =$AQ$2 -> 0.25 | AQ12: =IF(Table3[[#This Row],[Re-Order Rate %4]]-Table3[[#This Row],[Pre-Order Cancellations Mix %2]]-Table3[[#This Row],[Returns Rate %6]]<$AQ$1,$AQ$1,Table3[[#This Row],[Re-Order Rate %4]]-Table3[[#This Row],[Pre-Order Cancellations Mix %2]]-Table3[[#This Row],[Returns Rate %6]]) -> 0.68 | AR12: =Table3[[#This Row],[Pre-Orders Booked LYQ2 (shoes)]]*(1+Table3[[#This Row],[Re-Order Rate % FC]]+Table3[[#This Row],[Stock Clearance Rate %2]]+Table3[[#This Row],[Returns Rate %2]]-Table3[[#This Row],[FC Cancellation Mix %Shoes]]+Table3[[#This Row],[Exp Shoes PreOrder Growth Rate]]) -> 24383.081 | AS12: =Table3[[#This Row],[Tommaso''s FC Q2 SS5 Net Sales FC Shoes]]/Table3[[#This Row],[Net Sales Invoiced Shoes]]-1 -> 0.06943336 | AT12: =Table3[[#This Row],[Pre-Orders Booked LYQ2 (apparel)]]*(1+Table3[[#This Row],[Re-Order Rate % FC]]+Table3[[#This Row],[Stock Clearance Rate %2]]+Table3[[#This Row],[Returns Rate %2]]-Table3[[#This Row],[FC Cancellation Mix %Shoes]]+Table3[[#This Row],[Exp Apparel PreOrder Growth Rate]]) -> 6633.1361 | AU12: =Table3[[#This Row],[Tommaso''s FC Q2 SS5 Net Sales FC Apparel]]/Table3[[#This Row],[Net Sales Invoiced Apparel]]-1 -> 0.74556213 | AV12: 21000 | AW12: 1238 | AX12: =Table3[[#This Row],[Actual Order Book Shoes ]]/Table3[[#This Row],[Tommaso''s FC Q2 SS5 Net Sales FC Shoes]]-1 -> -0.13874705 | AY12: =Table3[[#This Row],[Actual Order Book Apparel ]]/Table3[[#This Row],[Tommaso''s FC Q2 SS5 Net Sales FC Apparel]]-1 -> -0.81336128 | AZ12: =Table3[[#This Row],[Actual Order Book Shoes ]]/Table3[[#This Row],[Net Sales Invoiced Shoes]]-1 -> -0.078947368 | BA12: =IFERROR(Table3[[#This Row],[Actual Order Book Apparel ]]/Table3[[#This Row],[Net Sales Invoiced Apparel]]-1,"") -> -0.67421053
A13: Central | B13: Switzerland | C13: Field Accounts | E13: 9000 | F13: 0.138 | G13: 0.689 | H13: 0 | I13: 0.118 | J13: 3600 | K13: 0.071 | L13: 0.963 | M13: 0 | N13: 0.111 | P13: =IFERROR(E13/(1-F13+G13+H13-I13),0) -> 6280.5304 | Q13: =IFERROR(J13/(1+L13+M13-N13-K13),0) -> 2021.3363 | R13: =E13+J13 -> 12600 | S13: ='SS24 Q2 Data'!$P19+Q13 -> 8814.5431 | T13: =ROUND(P13*F13,0) -> 867 | U13: =ROUND(P13*G13,0) -> 4327 | V13: =ROUND(P13*H13,0) -> 0 | W13: =ROUND(P13*I13,0) -> 741 | X13: =ROUND(Q13*K13,0) -> 144 | Y13: =ROUND(Q13*L13,0) -> 1947 | Z13: =ROUND(Q13*M13,0) -> 0 | AA13: =ROUND(Q13*M13,0) -> 0 | AB13: =J13/E13 -> 0.4 | AD13: =Table3[[#This Row],[Pre-Order Cancellations Mix Shoes]]+Table3[[#This Row],[Pre-Order Cancellations Mix %Apparel]] -> 1011 | AE13: =Table3[[#This Row],[Tot Cancellation]]/Table3[[#This Row],[Tot PreOrder Invoiced (units)]] -> 0.11469681 | AF13: =Table3[[#This Row],[Re-Order Rate %7]]+Table3[[#This Row],[Re-Order Rate %11]] -> 6274 | AG13: =Table3[[#This Row],[ToT Reorders]]/Table3[[#This Row],[Tot Net Sales Invoiced (units)]] -> 0.49793651 | AH13: =Table3[[#This Row],[Stock Clearance Rate %8]]+Table3[[#This Row],[Stock Clearance Rate %12]] -> 0 | AI13: =Table3[[#This Row],[ToT Stock Clearance]]/Table3[[#This Row],[Tot PreOrder Invoiced (units)]] -> 0 | AJ13: =Table3[[#This Row],[Returns Rate %13]]+Table3[[#This Row],[Returns Rate %9]] -> 741 | AK13: =Table3[[#This Row],[ToT Retruns]]/Table3[[#This Row],[Tot PreOrder Invoiced (units)]] -> 0.084065616 | AL13: 0.1 | AM13: 0.15 | AN13: 0.01 | AO13: 0.03 | AP13: =$AQ$2 -> 0.25 | AQ13: =IF(Table3[[#This Row],[Re-Order Rate %4]]-Table3[[#This Row],[Pre-Order Cancellations Mix %2]]-Table3[[#This Row],[Returns Rate %6]]<$AQ$1,$AQ$1,Table3[[#This Row],[Re-Order Rate %4]]-Table3[[#This Row],[Pre-Order Cancellations Mix %2]]-Table3[[#This Row],[Returns Rate %6]]) -> 0.781 | AR13: =Table3[[#This Row],[Pre-Orders Booked LYQ2 (shoes)]]*(1+Table3[[#This Row],[Re-Order Rate % FC]]+Table3[[#This Row],[Stock Clearance Rate %2]]+Table3[[#This Row],[Returns Rate %2]]-Table3[[#This Row],[FC Cancellation Mix %Shoes]]+Table3[[#This Row],[Exp Shoes PreOrder Growth Rate]]) -> 8415.9107 | AS13: =Table3[[#This Row],[Tommaso''s FC Q2 SS5 Net Sales FC Shoes]]/Table3[[#This Row],[Net Sales Invoiced Shoes]]-1 -> -0.064898814 | AT13: =Table3[[#This Row],[Pre-Orders Booked LYQ2 (apparel)]]*(1+Table3[[#This Row],[Re-Order Rate % FC]]+Table3[[#This Row],[Stock Clearance Rate %2]]+Table3[[#This Row],[Returns Rate %2]]-Table3[[#This Row],[FC Cancellation Mix %Shoes]]+Table3[[#This Row],[Exp Apparel PreOrder Growth Rate]]) -> 3781.9203 | AU13: =Table3[[#This Row],[Tommaso''s FC Q2 SS5 Net Sales FC Apparel]]/Table3[[#This Row],[Net Sales Invoiced Apparel]]-1 -> 0.050533408 | AV13: 8700 | AW13: 30324 | AX13: =Table3[[#This Row],[Actual Order Book Shoes ]]/Table3[[#This Row],[Tommaso''s FC Q2 SS5 Net Sales FC Shoes]]-1 -> 0.033756219 | AY13: =Table3[[#This Row],[Actual Order Book Apparel ]]/Table3[[#This Row],[Tommaso''s FC Q2 SS5 Net Sales FC Apparel]]-1 -> 7.0181489 | AZ13: =Table3[[#This Row],[Actual Order Book Shoes ]]/Table3[[#This Row],[Net Sales Invoiced Shoes]]-1 -> -0.033333333 | BA13: =IFERROR(Table3[[#This Row],[Actual Order Book Apparel ]]/Table3[[#This Row],[Net Sales Invoiced Apparel]]-1,"") -> 7.4233333
A14: North | B14: Nordics | C14: Field Accounts | E14: 5000 | F14: 0.13 | G14: 0.453 | H14: 0 | I14: 0.002 | J14: 400 | K14: 0.09 | L14: 0.106 | M14: 0 | N14: 0 | P14: =IFERROR(E14/(1-F14+G14+H14-I14),0) -> 3785.0114 | Q14: =IFERROR(J14/(1+L14+M14-N14-K14),0) -> 393.70079 | R14: =E14+J14 -> 5400 | S14: ='SS24 Q2 Data'!$P22+Q14 -> 1036.7876 | T14: =ROUND(P14*F14,0) -> 492 | U14: =ROUND(P14*G14,0) -> 1715 | V14: =ROUND(P14*H14,0) -> 0 | W14: =ROUND(P14*I14,0) -> 8 | X14: =ROUND(Q14*K14,0) -> 35 | Y14: =ROUND(Q14*L14,0) -> 42 | Z14: =ROUND(Q14*M14,0) -> 0 | AA14: =ROUND(Q14*M14,0) -> 0 | AB14: =J14/E14 -> 0.08 | AD14: =Table3[[#This Row],[Pre-Order Cancellations Mix Shoes]]+Table3[[#This Row],[Pre-Order Cancellations Mix %Apparel]] -> 527 | AE14: =Table3[[#This Row],[Tot Cancellation]]/Table3[[#This Row],[Tot PreOrder Invoiced (units)]] -> 0.50830083 | AF14: =Table3[[#This Row],[Re-Order Rate %7]]+Table3[[#This Row],[Re-Order Rate %11]] -> 1757 | AG14: =Table3[[#This Row],[ToT Reorders]]/Table3[[#This Row],[Tot Net Sales Invoiced (units)]] -> 0.32537037 | AH14: =Table3[[#This Row],[Stock Clearance Rate %8]]+Table3[[#This Row],[Stock Clearance Rate %12]] -> 0 | AI14: =Table3[[#This Row],[ToT Stock Clearance]]/Table3[[#This Row],[Tot PreOrder Invoiced (units)]] -> 0 | AJ14: =Table3[[#This Row],[Returns Rate %13]]+Table3[[#This Row],[Returns Rate %9]] -> 8 | AK14: =Table3[[#This Row],[ToT Retruns]]/Table3[[#This Row],[Tot PreOrder Invoiced (units)]] -> 0.0077161416 | AL14: 0.1 | AM14: 0.15 | AN14: 0.01 | AO14: 0.03 | AP14: =$AQ$2 -> 0.25 | AQ14: =IF(Table3[[#This Row],[Re-Order Rate %4]]-Table3[[#This Row],[Pre-Order Cancellations Mix %2]]-Table3[[#This Row],[Returns Rate %6]]<$AQ$1,$AQ$1,Table3[[#This Row],[Re-Order Rate %4]]-Table3[[#This Row],[Pre-Order Cancellations Mix %2]]-Table3[[#This Row],[Returns Rate %6]]) -> 0.68 | AR14: =Table3[[#This Row],[Pre-Orders Booked LYQ2 (shoes)]]*(1+Table3[[#This Row],[Re-Order Rate % FC]]+Table3[[#This Row],[Stock Clearance Rate %2]]+Table3[[#This Row],[Returns Rate %2]]-Table3[[#This Row],[FC Cancellation Mix %Shoes]]+Table3[[#This Row],[Exp Shoes PreOrder Growth Rate]]) -> 5071.9152 | AS14: =Table3[[#This Row],[Tommaso''s FC Q2 SS5 Net Sales FC Shoes]]/Table3[[#This Row],[Net Sales Invoiced Shoes]]-1 -> 0.014383043 | AT14: =Table3[[#This Row],[Pre-Orders Booked LYQ2 (apparel)]]*(1+Table3[[#This Row],[Re-Order Rate % FC]]+Table3[[#This Row],[Stock Clearance Rate %2]]+Table3[[#This Row],[Returns Rate %2]]-Table3[[#This Row],[FC Cancellation Mix %Shoes]]+Table3[[#This Row],[Exp Apparel PreOrder Growth Rate]]) -> 696.85039 | AU14: =Table3[[#This Row],[Tommaso''s FC Q2 SS5 Net Sales FC Apparel]]/Table3[[#This Row],[Net Sales Invoiced Apparel]]-1 -> 0.74212598 | AV14: 2200 | AW14: 2345 | AX14: =Table3[[#This Row],[Actual Order Book Shoes ]]/Table3[[#This Row],[Tommaso''s FC Q2 SS5 Net Sales FC Shoes]]-1 -> -0.56623881 | AY14: =Table3[[#This Row],[Actual Order Book Apparel ]]/Table3[[#This Row],[Tommaso''s FC Q2 SS5 Net Sales FC Apparel]]-1 -> 2.3651412 | AZ14: =Table3[[#This Row],[Actual Order Book Shoes ]]/Table3[[#This Row],[Net Sales Invoiced Shoes]]-1 -> -0.56 | BA14: =IFERROR(Table3[[#This Row],[Actual Order Book Apparel ]]/Table3[[#This Row],[Net Sales Invoiced Apparel]]-1,"") -> 4.8625
A15: South | B15: Italy | C15: Field Accounts | E15: 3000 | F15: 0.122 | G15: 1.892 | H15: 0 | I15: 1 | J15: 0 | K15: 1 | L15: 0 | M15: 0 | N15: 0 | P15: =IFERROR(E15/(1-F15+G15+H15-I15),0) -> 1694.9153 | Q15: =IFERROR(J15/(1+L15+M15-N15-K15),0) -> 0 | R15: =E15+J15 -> 3000 | S15: ='SS24 Q2 Data'!$P23+Q15 -> 417.05283 | T15: =ROUND(P15*F15,0) -> 207 | U15: =ROUND(P15*G15,0) -> 3207 | V15: =ROUND(P15*H15,0) -> 0 | W15: =ROUND(P15*I15,0) -> 1695 | X15: =ROUND(Q15*K15,0) -> 0 | Y15: =ROUND(Q15*L15,0) -> 0 | Z15: =ROUND(Q15*M15,0) -> 0 | AA15: =ROUND(Q15*M15,0) -> 0 | AB15: =J15/E15 -> 0 | AD15: =Table3[[#This Row],[Pre-Order Cancellations Mix Shoes]]+Table3[[#This Row],[Pre-Order Cancellations Mix %Apparel]] -> 207 | AE15: =Table3[[#This Row],[Tot Cancellation]]/Table3[[#This Row],[Tot PreOrder Invoiced (units)]] -> 0.49634 | AF15: =Table3[[#This Row],[Re-Order Rate %7]]+Table3[[#This Row],[Re-Order Rate %11]] -> 3207 | AG15: =Table3[[#This Row],[ToT Reorders]]/Table3[[#This Row],[Tot Net Sales Invoiced (units)]] -> 1.069 | AH15: =Table3[[#This Row],[Stock Clearance Rate %8]]+Table3[[#This Row],[Stock Clearance Rate %12]] -> 0 | AI15: =Table3[[#This Row],[ToT Stock Clearance]]/Table3[[#This Row],[Tot PreOrder Invoiced (units)]] -> 0 | AJ15: =Table3[[#This Row],[Returns Rate %13]]+Table3[[#This Row],[Returns Rate %9]] -> 1695 | AK15: =Table3[[#This Row],[ToT Retruns]]/Table3[[#This Row],[Tot PreOrder Invoiced (units)]] -> 4.0642333 | AL15: 0.1 | AM15: 0.15 | AN15: 0.01 | AO15: 0.03 | AP15: =$AQ$2 -> 0.25 | AQ15: NA | AR15: =Table3[[#This Row],[Pre-Orders Booked LYQ2 (shoes)]]*(1+Table3[[#This Row],[Re-Order Rate % FC]]+Table3[[#This Row],[Stock Clearance Rate %2]]+Table3[[#This Row],[Returns Rate %2]]-Table3[[#This Row],[FC Cancellation Mix %Shoes]]+Table3[[#This Row],[Exp Shoes PreOrder Growth Rate]]) -> 2271.1864 | AS15: =Table3[[#This Row],[Tommaso''s FC Q2 SS5 Net Sales FC Shoes]]/Table3[[#This Row],[Net Sales Invoiced Shoes]]-1 -> -0.24293785 | AT15: 500 | AU15: NA | AV15: 3300 | AW15: 345 | AX15: =Table3[[#This Row],[Actual Order Book Shoes ]]/Table3[[#This Row],[Tommaso''s FC Q2 SS5 Net Sales FC Shoes]]-1 -> 0.45298507 | AY15: =Table3[[#This Row],[Actual Order Book Apparel ]]/Table3[[#This Row],[Tommaso''s FC Q2 SS5 Net Sales FC Apparel]]-1 -> -0.31 | AZ15: =Table3[[#This Row],[Actual Order Book Shoes ]]/Table3[[#This Row],[Net Sales Invoiced Shoes]]-1 -> 0.1 | BA15: =IFERROR(Table3[[#This Row],[Actual Order Book Apparel ]]/Table3[[#This Row],[Net Sales Invoiced Apparel]]-1,"")
A16: North | B16: United Kingdom | C16: Titan Sport | D16: Monitor | E16: 36000 | F16: 0.553 | G16: 0 | H16: 0 | I16: 0.048 | J16: 2700 | K16: 0.655 | L16: 0 | M16: 0 | N16: 0.096 | P16: =IFERROR(E16/(1-F16+G16+H16-I16),0) -> 90225.564 | Q16: =IFERROR(J16/(1+L16+M16-N16-K16),0) -> 10843.373 | R16: =E16+J16 -> 38700 | S16: ='SS24 Q2 Data'!$P12+Q16 -> 29039.702 | T16: =ROUND(P16*F16,0) -> 49895 | U16: =ROUND(P16*G16,0) -> 0 | V16: =ROUND(P16*H16,0) -> 0 | W16: =ROUND(P16*I16,0) -> 4331 | X16: =ROUND(Q16*K16,0) -> 7102 | Y16: =ROUND(Q16*L16,0) -> 0 | Z16: =ROUND(Q16*M16,0) -> 0 | AA16: =ROUND(Q16*M16,0) -> 0 | AB16: =J16/E16 -> 0.075 | AD16: =Table3[[#This Row],[Pre-Order Cancellations Mix Shoes]]+Table3[[#This Row],[Pre-Order Cancellations Mix %Apparel]] -> 56997 | AE16: =Table3[[#This Row],[Tot Cancellation]]/Table3[[#This Row],[Tot PreOrder Invoiced (units)]] -> 1.9627267 | AF16: =Table3[[#This Row],[Re-Order Rate %7]]+Table3[[#This Row],[Re-Order Rate %11]] -> 0 | AG16: =Table3[[#This Row],[ToT Reorders]]/Table3[[#This Row],[Tot Net Sales Invoiced (units)]] -> 0 | AH16: =Table3[[#This Row],[Stock Clearance Rate %8]]+Table3[[#This Row],[Stock Clearance Rate %12]] -> 0 | AI16: =Table3[[#This Row],[ToT Stock Clearance]]/Table3[[#This Row],[Tot PreOrder Invoiced (units)]] -> 0 | AJ16: =Table3[[#This Row],[Returns Rate %13]]+Table3[[#This Row],[Returns Rate %9]] -> 4331 | AK16: =Table3[[#This Row],[ToT Retruns]]/Table3[[#This Row],[Tot PreOrder Invoiced (units)]] -> 0.14914065 | AL16: 0.06 | AM16: 0.15 | AN16: 0.01 | AO16: 0.03 | AP16: 0.1 | AQ16: 0.1 | AR16: =Table3[[#This Row],[Pre-Orders Booked LYQ2 (shoes)]]*(1+Table3[[#This Row],[Re-Order Rate % FC]]+Table3[[#This Row],[Stock Clearance Rate %2]]+Table3[[#This Row],[Returns Rate %2]]-Table3[[#This Row],[FC Cancellation Mix %Shoes]]+Table3[[#This Row],[Exp Shoes PreOrder Growth Rate]]) -> 110977.44 | AS16: =Table3[[#This Row],[Tommaso''s FC Q2 SS5 Net Sales FC Shoes]]/Table3[[#This Row],[Net Sales Invoiced Shoes]]-1 -> 2.0827068 | AT16: =Table3[[#This Row],[Pre-Orders Booked LYQ2 (apparel)]]*(1+Table3[[#This Row],[Re-Order Rate % FC]]+Table3[[#This Row],[Stock Clearance Rate %2]]+Table3[[#This Row],[Returns Rate %2]]-Table3[[#This Row],[FC Cancellation Mix %Shoes]]+Table3[[#This Row],[Exp Apparel PreOrder Growth Rate]]) -> 13337.349 | AU16: =Table3[[#This Row],[Tommaso''s FC Q2 SS5 Net Sales FC Apparel]]/Table3[[#This Row],[Net Sales Invoiced Apparel]]-1 -> 3.939759 | AV16: 24800 | AW16: 2345 | AX16: =Table3[[#This Row],[Actual Order Book Shoes ]]/Table3[[#This Row],[Tommaso''s FC Q2 SS5 Net Sales FC Shoes]]-1 -> -0.77653117 | AY16: =Table3[[#This Row],[Actual Order Book Apparel ]]/Table3[[#This Row],[Tommaso''s FC Q2 SS5 Net Sales FC Apparel]]-1 -> -0.82417796 | AZ16: =Table3[[#This Row],[Actual Order Book Shoes ]]/Table3[[#This Row],[Net Sales Invoiced Shoes]]-1 -> -0.31111111 | BA16: =IFERROR(Table3[[#This Row],[Actual Order Book Apparel ]]/Table3[[#This Row],[Net Sales Invoiced Apparel]]-1,"") -> -0.13148148
A17: Europe | B17: Europe | C17: Scale | D17: Core | E17: 213400 | F17: 0.061 | G17: 0 | H17: 0 | I17: 0.011 | J17: 24300 | K17: 0.073 | L17: 0.039 | M17: 0 | N17: 0.022 | P17: =IFERROR(E17/(1-F17+G17+H17-I17),0) -> 229956.9 | Q17: =IFERROR(J17/(1+L17+M17-N17-K17),0) -> 25741.525 | R17: =E17+J17 -> 237700 | S17: ='SS24 Q2 Data'!$P7+Q17 -> 57234.738 | T17: =ROUND(P17*F17,0) -> 14027 | U17: =ROUND(P17*G17,0) -> 0 | V17: =ROUND(P17*H17,0) -> 0 | W17: =ROUND(P17*I17,0) -> 2530 | X17: =ROUND(Q17*K17,0) -> 1879 | Y17: =ROUND(Q17*L17,0) -> 1004 | Z17: =ROUND(Q17*M17,0) -> 0 | AA17: =ROUND(Q17*M17,0) -> 0 | AB17: =J17/E17 -> 0.11387067 | AD17: =Table3[[#This Row],[Pre-Order Cancellations Mix Shoes]]+Table3[[#This Row],[Pre-Order Cancellations Mix %Apparel]] -> 15906 | AE17: =Table3[[#This Row],[Tot Cancellation]]/Table3[[#This Row],[Tot PreOrder Invoiced (units)]] -> 0.27790815 | AF17: =Table3[[#This Row],[Re-Order Rate %7]]+Table3[[#This Row],[Re-Order Rate %11]] -> 1004 | AG17: =Table3[[#This Row],[ToT Reorders]]/Table3[[#This Row],[Tot Net Sales Invoiced (units)]] -> 0.0042238115 | AH17: =Table3[[#This Row],[Stock Clearance Rate %8]]+Table3[[#This Row],[Stock Clearance Rate %12]] -> 0 | AI17: =Table3[[#This Row],[ToT Stock Clearance]]/Table3[[#This Row],[Tot PreOrder Invoiced (units)]] -> 0 | AJ17: =Table3[[#This Row],[Returns Rate %13]]+Table3[[#This Row],[Returns Rate %9]] -> 2530 | AK17: =Table3[[#This Row],[ToT Retruns]]/Table3[[#This Row],[Tot PreOrder Invoiced (units)]] -> 0.044203924 | AL17: 0.06 | AM17: 0.1 | AN17: 0.01 | AO17: 0.03 | AP17: =$AQ$2 -> 0.25 | AQ17: =IF(Table3[[#This Row],[Re-Order Rate %4]]-Table3[[#This Row],[Pre-Order Cancellations Mix %2]]-Table3[[#This Row],[Returns Rate %6]]<$AQ$1,$AQ$1,Table3[[#This Row],[Re-Order Rate %4]]-Table3[[#This Row],[Pre-Order Cancellations Mix %2]]-Table3[[#This Row],[Returns Rate %6]]) -> 0.68 | AR17: =Table3[[#This Row],[Pre-Orders Booked LYQ2 (shoes)]]*(1+Table3[[#This Row],[Re-Order Rate % FC]]+Table3[[#This Row],[Stock Clearance Rate %2]]+Table3[[#This Row],[Returns Rate %2]]-Table3[[#This Row],[FC Cancellation Mix %Shoes]]+Table3[[#This Row],[Exp Shoes PreOrder Growth Rate]]) -> 305842.67 | AS17: =Table3[[#This Row],[Tommaso''s FC Q2 SS5 Net Sales FC Shoes]]/Table3[[#This Row],[Net Sales Invoiced Shoes]]-1 -> 0.43318966 | AT17: =Table3[[#This Row],[Pre-Orders Booked LYQ2 (apparel)]]*(1+Table3[[#This Row],[Re-Order Rate % FC]]+Table3[[#This Row],[Stock Clearance Rate %2]]+Table3[[#This Row],[Returns Rate %2]]-Table3[[#This Row],[FC Cancellation Mix %Shoes]]+Table3[[#This Row],[Exp Apparel PreOrder Growth Rate]]) -> 45305.085 | AU17: =Table3[[#This Row],[Tommaso''s FC Q2 SS5 Net Sales FC Apparel]]/Table3[[#This Row],[Net Sales Invoiced Apparel]]-1 -> 0.86440678 | AV17: 256100 | AW17: 25435 | AX17: =Table3[[#This Row],[Actual Order Book Shoes ]]/Table3[[#This Row],[Tommaso''s FC Q2 SS5 Net Sales FC Shoes]]-1 -> -0.16264137 | AY17: =Table3[[#This Row],[Actual Order Book Apparel ]]/Table3[[#This Row],[Tommaso''s FC Q2 SS5 Net Sales FC Apparel]]-1 -> -0.43858399 | AZ17: =Table3[[#This Row],[Actual Order Book Shoes ]]/Table3[[#This Row],[Net Sales Invoiced Shoes]]-1 -> 0.20009372 | BA17: =IFERROR(Table3[[#This Row],[Actual Order Book Apparel ]]/Table3[[#This Row],[Net Sales Invoiced Apparel]]-1,"") -> 0.046707819
A18: Europe | B18: Europe | C18: Vault | D18: Core | E18: 95400 | F18: 0.093 | G18: 0.017 | H18: 0 | I18: 0.047 | J18: 0 | K18: 0 | L18: 0 | M18: 0 | N18: 0 | P18: =IFERROR(E18/(1-F18+G18+H18-I18),0) -> 108779.93 | Q18: =IFERROR(J18/(1+L18+M18-N18-K18),0) -> 0 | R18: =E18+J18 -> 95400 | S18: ='SS24 Q2 Data'!$P9+Q18 -> 53947.368 | T18: =ROUND(P18*F18,0) -> 10117 | U18: =ROUND(P18*G18,0) -> 1849 | V18: =ROUND(P18*H18,0) -> 0 | W18: =ROUND(P18*I18,0) -> 5113 | X18: =ROUND(Q18*K18,0) -> 0 | Y18: =ROUND(Q18*L18,0) -> 0 | Z18: =ROUND(Q18*M18,0) -> 0 | AA18: =ROUND(Q18*M18,0) -> 0 | AB18: =J18/E18 -> 0 | AD18: =Table3[[#This Row],[Pre-Order Cancellations Mix Shoes]]+Table3[[#This Row],[Pre-Order Cancellations Mix %Apparel]] -> 10117 | AE18: =Table3[[#This Row],[Tot Cancellation]]/Table3[[#This Row],[Tot PreOrder Invoiced (units)]] -> 0.18753463 | AF18: =Table3[[#This Row],[Re-Order Rate %7]]+Table3[[#This Row],[Re-Order Rate %11]] -> 1849 | AG18: =Table3[[#This Row],[ToT Reorders]]/Table3[[#This Row],[Tot Net Sales Invoiced (units)]] -> 0.019381551 | AH18: =Table3[[#This Row],[Stock Clearance Rate %8]]+Table3[[#This Row],[Stock Clearance Rate %12]] -> 0 | AI18: =Table3[[#This Row],[ToT Stock Clearance]]/Table3[[#This Row],[Tot PreOrder Invoiced (units)]] -> 0 | AJ18: =Table3[[#This Row],[Returns Rate %13]]+Table3[[#This Row],[Returns Rate %9]] -> 5113 | AK18: =Table3[[#This Row],[ToT Retruns]]/Table3[[#This Row],[Tot PreOrder Invoiced (units)]] -> 0.094777561 | AL18: 0.06 | AM18: 0.1 | AN18: 0.01 | AO18: 0.03 | AP18: =$AQ$2 -> 0.25 | AQ18: NA | AR18: =Table3[[#This Row],[Pre-Orders Booked LYQ2 (shoes)]]*(1+Table3[[#This Row],[Re-Order Rate % FC]]+Table3[[#This Row],[Stock Clearance Rate %2]]+Table3[[#This Row],[Returns Rate %2]]-Table3[[#This Row],[FC Cancellation Mix %Shoes]]+Table3[[#This Row],[Exp Shoes PreOrder Growth Rate]]) -> 144677.31 | AS18: =Table3[[#This Row],[Tommaso''s FC Q2 SS5 Net Sales FC Shoes]]/Table3[[#This Row],[Net Sales Invoiced Shoes]]-1 -> 0.51653364 | AT18: 10000 | AU18: NA | AV18: 124000 | AW18: 0 | AX18: =Table3[[#This Row],[Actual Order Book Shoes ]]/Table3[[#This Row],[Tommaso''s FC Q2 SS5 Net Sales FC Shoes]]-1 -> -0.14292019 | AY18: =Table3[[#This Row],[Actual Order Book Apparel ]]/Table3[[#This Row],[Tommaso''s FC Q2 SS5 Net Sales FC Apparel]]-1 -> -1 | AZ18: =Table3[[#This Row],[Actual Order Book Shoes ]]/Table3[[#This Row],[Net Sales Invoiced Shoes]]-1 -> 0.29979036 | BA18: =IFERROR(Table3[[#This Row],[Actual Order Book Apparel ]]/Table3[[#This Row],[Net Sales Invoiced Apparel]]-1,"")
A19: North | B19: France | C19: Swift-Pulse | D19: Opportunity | E19: 6800 | F19: 0.036 | G19: 0.037 | H19: 0 | I19: 0 | J19: 0 | K19: 0 | L19: 0 | M19: 0 | N19: 0 | P19: =IFERROR(E19/(1-F19+G19+H19-I19),0) -> 6793.2068 | Q19: =IFERROR(J19/(1+L19+M19-N19-K19),0) -> 0 | R19: =E19+J19 -> 6800 | S19: ='SS24 Q2 Data'!$P21+Q19 -> 1200 | T19: =ROUND(P19*F19,0) -> 245 | U19: =ROUND(P19*G19,0) -> 251 | V19: =ROUND(P19*H19,0) -> 0 | W19: =ROUND(P19*I19,0) -> 0 | X19: =ROUND(Q19*K19,0) -> 0 | Y19: =ROUND(Q19*L19,0) -> 0 | Z19: =ROUND(Q19*M19,0) -> 0 | AA19: =ROUND(Q19*M19,0) -> 0 | AB19: =J19/E19 -> 0 | AD19: =Table3[[#This Row],[Pre-Order Cancellations Mix Shoes]]+Table3[[#This Row],[Pre-Order Cancellations Mix %Apparel]] -> 245 | AE19: =Table3[[#This Row],[Tot Cancellation]]/Table3[[#This Row],[Tot PreOrder Invoiced (units)]] -> 0.20416667 | AF19: =Table3[[#This Row],[Re-Order Rate %7]]+Table3[[#This Row],[Re-Order Rate %11]] -> 251 | AG19: =Table3[[#This Row],[ToT Reorders]]/Table3[[#This Row],[Tot Net Sales Invoiced (units)]] -> 0.036911765 | AH19: =Table3[[#This Row],[Stock Clearance Rate %8]]+Table3[[#This Row],[Stock Clearance Rate %12]] -> 0 | AI19: =Table3[[#This Row],[ToT Stock Clearance]]/Table3[[#This Row],[Tot PreOrder Invoiced (units)]] -> 0 | AJ19: =Table3[[#This Row],[Returns Rate %13]]+Table3[[#This Row],[Returns Rate %9]] -> 0 | AK19: =Table3[[#This Row],[ToT Retruns]]/Table3[[#This Row],[Tot PreOrder Invoiced (units)]] -> 0 | AL19: 0.03 | AM19: 0.3 | AN19: 0.01 | AO19: 0.03 | AP19: =$AQ$2 -> 0.25 | AQ19: NA | AR19: =Table3[[#This Row],[Pre-Orders Booked LYQ2 (shoes)]]*(1+Table3[[#This Row],[Re-Order Rate % FC]]+Table3[[#This Row],[Stock Clearance Rate %2]]+Table3[[#This Row],[Returns Rate %2]]-Table3[[#This Row],[FC Cancellation Mix %Shoes]]+Table3[[#This Row],[Exp Shoes PreOrder Growth Rate]]) -> 10597.403 | AS19: =Table3[[#This Row],[Tommaso''s FC Q2 SS5 Net Sales FC Shoes]]/Table3[[#This Row],[Net Sales Invoiced Shoes]]-1 -> 0.55844156 | AT19: 1500 | AU19: NA | AV19: 2300 | AW19: 324 | AX19: =Table3[[#This Row],[Actual Order Book Shoes ]]/Table3[[#This Row],[Tommaso''s FC Q2 SS5 Net Sales FC Shoes]]-1 -> -0.78296569 | AY19: =Table3[[#This Row],[Actual Order Book Apparel ]]/Table3[[#This Row],[Tommaso''s FC Q2 SS5 Net Sales FC Apparel]]-1 -> -0.784 | AZ19: =Table3[[#This Row],[Actual Order Book Shoes ]]/Table3[[#This Row],[Net Sales Invoiced Shoes]]-1 -> -0.66176471 | BA19: =IFERROR(Table3[[#This Row],[Actual Order Book Apparel ]]/Table3[[#This Row],[Net Sales Invoiced Apparel]]-1,"")
A20: North | B20: BeNeLux | C20: Vanguard Wilds | D20: Opportunity | E20: 2000 | F20: 0 | G20: 0 | H20: 0 | I20: 0 | J20: 250 | K20: 0 | L20: 0 | M20: 0 | N20: 0 | P20: =IFERROR(E20/(1-F20+G20+H20-I20),0) -> 2000 | Q20: =IFERROR(J20/(1+L20+M20-N20-K20),0) -> 250 | R20: =E20+J20 -> 2250 | S20: ='SS24 Q2 Data'!$P24+Q20 -> 250 | T20: =ROUND(P20*F20,0) -> 0 | U20: =ROUND(P20*G20,0) -> 0 | V20: =ROUND(P20*H20,0) -> 0 | W20: =ROUND(P20*I20,0) -> 0 | X20: =ROUND(Q20*K20,0) -> 0 | Y20: =ROUND(Q20*L20,0) -> 0 | Z20: =ROUND(Q20*M20,0) -> 0 | AA20: =ROUND(Q20*M20,0) -> 0 | AB20: =J20/E20 -> 0.125 | AD20: =Table3[[#This Row],[Pre-Order Cancellations Mix Shoes]]+Table3[[#This Row],[Pre-Order Cancellations Mix %Apparel]] -> 0 | AE20: =Table3[[#This Row],[Tot Cancellation]]/Table3[[#This Row],[Tot PreOrder Invoiced (units)]] -> 0 | AF20: =Table3[[#This Row],[Re-Order Rate %7]]+Table3[[#This Row],[Re-Order Rate %11]] -> 0 | AG20: =Table3[[#This Row],[ToT Reorders]]/Table3[[#This Row],[Tot Net Sales Invoiced (units)]] -> 0 | AH20: =Table3[[#This Row],[Stock Clearance Rate %8]]+Table3[[#This Row],[Stock Clearance Rate %12]] -> 0 | AI20: =Table3[[#This Row],[ToT Stock Clearance]]/Table3[[#This Row],[Tot PreOrder Invoiced (units)]] -> 0 | AJ20: =Table3[[#This Row],[Returns Rate %13]]+Table3[[#This Row],[Returns Rate %9]] -> 0 | AK20: =Table3[[#This Row],[ToT Retruns]]/Table3[[#This Row],[Tot PreOrder Invoiced (units)]] -> 0 | AL20: 0.03 | AM20: 0.3 | AN20: 0.01 | AO20: 0.03 | AP20: =$AQ$2 -> 0.25 | AQ20: =IF(Table3[[#This Row],[Re-Order Rate %4]]-Table3[[#This Row],[Pre-Order Cancellations Mix %2]]-Table3[[#This Row],[Returns Rate %6]]<$AQ$1,$AQ$1,Table3[[#This Row],[Re-Order Rate %4]]-Table3[[#This Row],[Pre-Order Cancellations Mix %2]]-Table3[[#This Row],[Returns Rate %6]]) -> 0.68 | AR20: =Table3[[#This Row],[Pre-Orders Booked LYQ2 (shoes)]]*(1+Table3[[#This Row],[Re-Order Rate % FC]]+Table3[[#This Row],[Stock Clearance Rate %2]]+Table3[[#This Row],[Returns Rate %2]]-Table3[[#This Row],[FC Cancellation Mix %Shoes]]+Table3[[#This Row],[Exp Shoes PreOrder Growth Rate]]) -> 3120 | AS20: =Table3[[#This Row],[Tommaso''s FC Q2 SS5 Net Sales FC Shoes]]/Table3[[#This Row],[Net Sales Invoiced Shoes]]-1 -> 0.56 | AT20: =Table3[[#This Row],[Pre-Orders Booked LYQ2 (apparel)]]*(1+Table3[[#This Row],[Re-Order Rate % FC]]+Table3[[#This Row],[Stock Clearance Rate %2]]+Table3[[#This Row],[Returns Rate %2]]-Table3[[#This Row],[FC Cancellation Mix %Shoes]]+Table3[[#This Row],[Exp Apparel PreOrder Growth Rate]]) -> 497.5 | AU20: =Table3[[#This Row],[Tommaso''s FC Q2 SS5 Net Sales FC Apparel]]/Table3[[#This Row],[Net Sales Invoiced Apparel]]-1 -> 0.99 | AV20: 600 | AW20: 0 | AX20: =Table3[[#This Row],[Actual Order Book Shoes ]]/Table3[[#This Row],[Tommaso''s FC Q2 SS5 Net Sales FC Shoes]]-1 -> -0.80769231 | AY20: =Table3[[#This Row],[Actual Order Book Apparel ]]/Table3[[#This Row],[Tommaso''s FC Q2 SS5 Net Sales FC Apparel]]-1 -> -1 | AZ20: =Table3[[#This Row],[Actual Order Book Shoes ]]/Table3[[#This Row],[Net Sales Invoiced Shoes]]-1 -> -0.7 | BA20: =IFERROR(Table3[[#This Row],[Actual Order Book Apparel ]]/Table3[[#This Row],[Net Sales Invoiced Apparel]]-1,"") -> -1
A21: Europe | B21: Europe | C21: Strike-Point | D21: Opportunity | E21: 1200 | F21: 0 | G21: 0 | H21: 0 | I21: 0 | J21: 0 | K21: 0 | L21: 0 | M21: 0 | N21: 0 | P21: =IFERROR(E21/(1-F21+G21+H21-I21),0) -> 1200 | Q21: =IFERROR(J21/(1+L21+M21-N21-K21),0) -> 0 | R21: =E21+J21 -> 1200 | S21: ='SS24 Q2 Data'!$P25+Q21 -> 284.09091 | T21: =ROUND(P21*F21,0) -> 0 | U21: =ROUND(P21*G21,0) -> 0 | V21: =ROUND(P21*H21,0) -> 0 | W21: =ROUND(P21*I21,0) -> 0 | X21: =ROUND(Q21*K21,0) -> 0 | Y21: =ROUND(Q21*L21,0) -> 0 | Z21: =ROUND(Q21*M21,0) -> 0 | AA21: =ROUND(Q21*M21,0) -> 0 | AB21: =J21/E21 -> 0 | AD21: =Table3[[#This Row],[Pre-Order Cancellations Mix Shoes]]+Table3[[#This Row],[Pre-Order Cancellations Mix %Apparel]] -> 0 | AE21: =Table3[[#This Row],[Tot Cancellation]]/Table3[[#This Row],[Tot PreOrder Invoiced (units)]] -> 0 | AF21: =Table3[[#This Row],[Re-Order Rate %7]]+Table3[[#This Row],[Re-Order Rate %11]] -> 0 | AG21: =Table3[[#This Row],[ToT Reorders]]/Table3[[#This Row],[Tot Net Sales Invoiced (units)]] -> 0 | AH21: =Table3[[#This Row],[Stock Clearance Rate %8]]+Table3[[#This Row],[Stock Clearance Rate %12]] -> 0 | AI21: =Table3[[#This Row],[ToT Stock Clearance]]/Table3[[#This Row],[Tot PreOrder Invoiced (units)]] -> 0 | AJ21: =Table3[[#This Row],[Returns Rate %13]]+Table3[[#This Row],[Returns Rate %9]] -> 0 | AK21: =Table3[[#This Row],[ToT Retruns]]/Table3[[#This Row],[Tot PreOrder Invoiced (units)]] -> 0 | AL21: 0.03 | AM21: 0.3 | AN21: 0.01 | AO21: 0.03 | AP21: =$AQ$2 -> 0.25 | AQ21: NA | AR21: =Table3[[#This Row],[Pre-Orders Booked LYQ2 (shoes)]]*(1+Table3[[#This Row],[Re-Order Rate % FC]]+Table3[[#This Row],[Stock Clearance Rate %2]]+Table3[[#This Row],[Returns Rate %2]]-Table3[[#This Row],[FC Cancellation Mix %Shoes]]+Table3[[#This Row],[Exp Shoes PreOrder Growth Rate]]) -> 1872 | AS21: =Table3[[#This Row],[Tommaso''s FC Q2 SS5 Net Sales FC Shoes]]/Table3[[#This Row],[Net Sales Invoiced Shoes]]-1 -> 0.56 | AT21: 500 | AU21: NA | AV21: 2400 | AW21: 123 | AX21: =Table3[[#This Row],[Actual Order Book Shoes ]]/Table3[[#This Row],[Tommaso''s FC Q2 SS5 Net Sales FC Shoes]]-1 -> 0.28205128 | AY21: =Table3[[#This Row],[Actual Order Book Apparel ]]/Table3[[#This Row],[Tommaso''s FC Q2 SS5 Net Sales FC Apparel]]-1 -> -0.754 | AZ21: =Table3[[#This Row],[Actual Order Book Shoes ]]/Table3[[#This Row],[Net Sales Invoiced Shoes]]-1 -> 1 | BA21: =IFERROR(Table3[[#This Row],[Actual Order Book Apparel ]]/Table3[[#This Row],[Net Sales Invoiced Apparel]]-1,"")
